<?xml version="1.0"?>
<!-- =================================================================================== -->
<!-- |    This document was autogenerated by xacro from panda_arm_hand.urdf.xacro      | -->
<!-- |    EDITING THIS FILE BY HAND IS NOT RECOMMENDED                                 | -->
<!-- =================================================================================== -->
<robot xmlns:xacro="http://www.ros.org/wiki/xacro" name="panda">
  <link name="panda_zbase">
    <inertial>
      <origin rpy="0 0 0" xyz="0 0 0"/>
      <mass value=".0"/>
      <inertia ixx="0" ixy="0" ixz="0" iyy="0" iyz="0" izz="0"/>
    </inertial>
    <visual>
      <geometry>
        <box size="0.1 0.1 0.5"/>
      </geometry>
    </visual>
    <collision>
      <geometry>
        <box size="0.1 0.1 0.5"/>
      </geometry>
      <material name="panda_white"/>
    </collision>
  </link>
  <link name="panda_xbase">
  </link>
  <link name="panda_ybase">
  </link>
  <link name="panda_wbase">
  </link>
  <link name="panda_hand">
    <inertial>
      <origin rpy="0 0 0" xyz="0 0 0.04"/>
      <mass value=".81"/>
      <inertia ixx="0.1" ixy="0" ixz="0" iyy="0.1" iyz="0" izz="0.1"/>
    </inertial>
    <visual>
      <geometry>
        <mesh filename="package://meshes/visual/hand.obj"/>
      </geometry>
      <material name="panda_white">
        <color rgba="1. 1. 1. 1."/>
      </material>
    </visual>
    <collision>
      <geometry>
        <mesh filename="package://meshes/collision/hand.obj"/>
      </geometry>
      <material name="panda_white"/>
    </collision>
  </link>
  <link name="panda_rightfinger">
    <inertial>
      <origin rpy="0 0 0" xyz="0.0 -0.0192 0.0162"/>
      <mass value="0.026"/>
      <inertia ixx="0.00000613982" ixy="0" ixz="0" iyy="0.000001452" iyz="-0.0000005264" izz="0.0000064"/>
    </inertial>
    <visual>
      <geometry>
        <mesh filename="package://meshes/visual/finger_visual.obj"/>
      </geometry>
      <material name="panda_white"/>
    </visual>
    <collision>
      <geometry>
        <mesh filename="package://meshes/collision/finger_collider.obj"/>
      </geometry>
      <material name="panda_white"/>
    </collision>
  </link>
  <link name="panda_rightfingerpad">
    <contact>
      <friction_anchor/>
      <stiffness value="30000.0"/>
      <damping value="1.0"/>
      <spinning_friction value="0.1"/>
      <lateral_friction value="1.0"/>
    </contact>
    <inertial>
      <origin rpy="0 0 0" xyz="0 0. 0"/>
      <!--<mass value="0.003"/>-->
      <mass value="0.0000000000003"/> <!-- Small mass to not affect the FT readings -->
      <inertia ixx="0.0000001038" ixy="0" ixz="0" iyy="0.0000001039" iyz="0" izz="0.000000162"/>
    </inertial>
    <visual>
      <geometry>
        <mesh filename="package://meshes/visual/fingerpad_visual2.obj"/>
      </geometry>
    </visual>
    <collision>
      <geometry>
        <mesh filename="package://meshes/collision/fingerpad_collider2.obj"/>
      </geometry>
    </collision>
  </link>
  <link name="panda_leftfinger">
    <contact>
      <friction_anchor/>
      <stiffness value="30000.0"/>
      <damping value="1.0"/>
      <spinning_friction value="0.1"/>
      <lateral_friction value="1.0"/>
    </contact>
    <inertial>
      <origin rpy="0 0 0" xyz="0.0 -0.0192 0.0162"/>
      <mass value="0.026"/>
      <inertia ixx="0.00000613982" ixy="0" ixz="0" iyy="0.000001452" iyz="-0.0000005264" izz="0.0000064"/>
    </inertial>
    <visual>
      <origin rpy="0 0 3.14159265359" xyz="0 0 0"/>
      <geometry>
        <mesh filename="package://meshes/visual/finger_visual.obj"/>
      </geometry>
      <material name="panda_white"/>
    </visual>
    <collision>
      <origin rpy="0 0 3.14159265359" xyz="0 0 0"/>
      <geometry>
        <mesh filename="package://meshes/collision/finger_collider.obj"/>
      </geometry>
    </collision>
  </link>
  <link name="panda_leftfingerpad">
    <contact>
      <friction_anchor/>
      <stiffness value="30000.0"/>
      <damping value="1000.0"/>
      <spinning_friction value="0.1"/>
      <lateral_friction value="1.0"/>
    </contact>
    <inertial>
      <origin rpy="0 0 0" xyz="0 0. 0"/>
      <!--<mass value="0.003"/>-->
      <mass value="0.0000000000003"/> <!-- Small mass to not affect the FT readings -->
      <inertia ixx="0.0000001038" ixy="0" ixz="0" iyy="0.0000001039" iyz="0" izz="0.000000162"/>
    </inertial>
    <visual>
      <origin rpy="0 0 3.14159265359" xyz="0 0 0"/>
      <geometry>
        <mesh filename="package://meshes/visual/fingerpad_visual2.obj"/>
      </geometry>
    </visual>
    <collision>
      <origin rpy="0 0 3.14159265359" xyz="0 0 0"/>
      <geometry>
        <mesh filename="package://meshes/collision/fingerpad_collider2.obj"/>
      </geometry>
      <material name="panda_white"/>
    </collision>
  </link>
  <joint name="panda_xbase_zbase" type="prismatic">
    <parent link="panda_zbase"/>
    <child link="panda_xbase"/>
    <origin rpy="1.57079632679 0 0" xyz="0.1 0 0.1"/>
    <axis xyz="0 1 0"/>
    <limit effort="1000" lower="-0.5" upper="1.0" velocity="5.0"/>
  </joint>
  <joint name="panda_hand_xbase" type="prismatic">
    <parent link="panda_xbase"/>
    <child link="panda_ybase"/>
    <origin rpy="1.57079632679 0 1.57079632679" xyz="0. 0. 0."/>
    <axis xyz="0 1 0"/>
    <limit effort="10" velocity="0.1"/>
  </joint>
  <joint name="panda_hand_ybase" type="prismatic">
    <parent link="panda_ybase"/>
    <child link="panda_wbase"/>
    <origin rpy="0 0 0" xyz="0. 0. 0."/>
    <axis xyz="0 0 1"/>
    <limit effort="10" velocity="0.1"/>
  </joint>
  <joint name="panda_hand_wbase" type="revolute">
    <parent link="panda_wbase"/>
    <child link="panda_hand"/>
    <origin rpy="0 0 0" xyz="0. 0. 0."/>
    <axis xyz="1 0 0"/>
    <limit effort="10" velocity="0.02"/>
  </joint>
  <joint name="panda_finger_right" type="prismatic">
    <parent link="panda_hand"/>
    <child link="panda_rightfinger"/>
    <origin rpy="0 0 0" xyz="0 0 0.0584"/>
    <axis xyz="0 1 0"/>
    <dynamics damping="0.3" friction="0.0"/>
    <limit effort="20" lower="0.0" upper="0.04" velocity="0.2"/>
  </joint>
  <joint name="panda_right_fingerpad_joint" type="fixed">
    <parent link="panda_rightfinger"/>
    <child link="panda_rightfingerpad"/>
    <origin rpy="0 0 0" xyz="0 0 0.045"/>
  </joint>
  <joint name="panda_finger_left" type="prismatic">
    <parent link="panda_hand"/>
    <child link="panda_leftfinger"/>
    <origin rpy="0 0 0" xyz="0 0 0.0584"/>
    <axis xyz="0 -1 0"/>
    <dynamics damping="0.3" friction="0.0"/>
    <limit effort="20" lower="0.0" upper="0.04" velocity="0.2"/>
  </joint>
  <joint name="panda_left_fingerpad_joint" type="fixed">
    <parent link="panda_leftfinger"/>
    <child link="panda_leftfingerpad"/>
    <origin rpy="0 0 0" xyz="0 0 0.045"/>
  </joint>
</robot>
